cpp/tests/test_20240229113636.in
50
0-49 o
0 B 1 META 1234 30
0 S 2 NFLX 2345 1
0 C 1
0 S 3 NVDA 1357 25
0 B 4 NFLX 2469 10
0 C 2
1 B 5 AMZN 1234 30
1 S 6 MSFT 2345 1
1 C 5
1 S 7 AMZN 1357 25
1 B 8 AMZN 2469 10
1 C 6
2 B 9 AMZN 1234 30
2 S 10 MSFT 2345 1
2 C 9
2 S 11 INTC 1357 25
2 B 12 AMD 2469 10
2 C 10
3 B 13 META 1234 30
3 S 14 INTC 2345 1
3 C 13
3 S 15 AAPL 1357 25
3 B 16 GOOGL 2469 10
3 C 14
4 B 17 MSFT 1234 30
4 S 18 INTC 2345 1
4 C 17
4 S 19 AAPL 1357 25
4 B 20 INTC 2469 10
4 C 18
5 B 21 AAPL 1234 30
5 S 22 GOOGL 2345 1
5 C 21
5 S 23 META 1357 25
5 B 24 NFLX 2469 10
5 C 22
6 B 25 NFLX 1234 30
6 S 26 INTC 2345 1
6 C 25
6 S 27 NVDA 1357 25
6 B 28 META 2469 10
6 C 26
7 B 29 INTC 1234 30
7 S 30 AMZN 2345 1
7 C 29
7 S 31 GOOGL 1357 25
7 B 32 INTC 2469 10
7 C 30
8 B 33 NFLX 1234 30
8 S 34 GOOGL 2345 1
8 C 33
8 S 35 META 1357 25
8 B 36 INTC 2469 10
8 C 34
9 B 37 AMD 1234 30
9 S 38 META 2345 1
9 C 37
9 S 39 AAPL 1357 25
9 B 40 NVDA 2469 10
9 C 38
10 B 41 INTC 1234 30
10 S 42 TSLA 2345 1
10 C 41
10 S 43 GOOGL 1357 25
10 B 44 MSFT 2469 10
10 C 42
11 B 45 META 1234 30
11 S 46 AAPL 2345 1
11 C 45
11 S 47 AMZN 1357 25
11 B 48 GOOGL 2469 10
11 C 46
12 B 49 GOOGL 1234 30
12 S 50 INTC 2345 1
12 C 49
12 S 51 TSLA 1357 25
12 B 52 GOOGL 2469 10
12 C 50
13 B 53 META 1234 30
13 S 54 AAPL 2345 1
13 C 53
13 S 55 MSFT 1357 25
13 B 56 INTC 2469 10
13 C 54
14 B 57 NFLX 1234 30
14 S 58 AMD 2345 1
14 C 57
14 S 59 TSLA 1357 25
14 B 60 NVDA 2469 10
14 C 58
15 B 61 TSLA 1234 30
15 S 62 TSLA 2345 1
15 C 61
15 S 63 MSFT 1357 25
15 B 64 AAPL 2469 10
15 C 62
16 B 65 NFLX 1234 30
16 S 66 AMZN 2345 1
16 C 65
16 S 67 META 1357 25
16 B 68 TSLA 2469 10
16 C 66
17 B 69 GOOGL 1234 30
17 S 70 AMZN 2345 1
17 C 69
17 S 71 AMD 1357 25
17 B 72 GOOGL 2469 10
17 C 70
18 B 73 META 1234 30
18 S 74 TSLA 2345 1
18 C 73
18 S 75 INTC 1357 25
18 B 76 NVDA 2469 10
18 C 74
19 B 77 NFLX 1234 30
19 S 78 INTC 2345 1
19 C 77
19 S 79 AAPL 1357 25
19 B 80 INTC 2469 10
19 C 78
20 B 81 MSFT 1234 30
20 S 82 META 2345 1
20 C 81
20 S 83 AMD 1357 25
20 B 84 INTC 2469 10
20 C 82
21 B 85 NFLX 1234 30
21 S 86 INTC 2345 1
21 C 85
21 S 87 AMZN 1357 25
21 B 88 NVDA 2469 10
21 C 86
22 B 89 AMD 1234 30
22 S 90 GOOGL 2345 1
22 C 89
22 S 91 MSFT 1357 25
22 B 92 INTC 2469 10
22 C 90
23 B 93 MSFT 1234 30
23 S 94 AAPL 2345 1
23 C 93
23 S 95 GOOGL 1357 25
23 B 96 AMD 2469 10
23 C 94
24 B 97 NFLX 1234 30
24 S 98 AAPL 2345 1
24 C 97
24 S 99 GOOGL 1357 25
24 B 100 MSFT 2469 10
24 C 98
25 B 101 AMD 1234 30
25 S 102 NVDA 2345 1
25 C 101
25 S 103 META 1357 25
25 B 104 AAPL 2469 10
25 C 102
26 B 105 NVDA 1234 30
26 S 106 TSLA 2345 1
26 C 105
26 S 107 TSLA 1357 25
26 B 108 GOOGL 2469 10
26 C 106
27 B 109 GOOGL 1234 30
27 S 110 AMZN 2345 1
27 C 109
27 S 111 AMD 1357 25
27 B 112 TSLA 2469 10
27 C 110
28 B 113 TSLA 1234 30
28 S 114 INTC 2345 1
28 C 113
28 S 115 NFLX 1357 25
28 B 116 NVDA 2469 10
28 C 114
29 B 117 AAPL 1234 30
29 S 118 MSFT 2345 1
29 C 117
29 S 119 AMZN 1357 25
29 B 120 NFLX 2469 10
29 C 118
30 B 121 AMZN 1234 30
30 S 122 GOOGL 2345 1
30 C 121
30 S 123 GOOGL 1357 25
30 B 124 NVDA 2469 10
30 C 122
31 B 125 AMD 1234 30
31 S 126 TSLA 2345 1
31 C 125
31 S 127 AAPL 1357 25
31 B 128 GOOGL 2469 10
31 C 126
32 B 129 TSLA 1234 30
32 S 130 META 2345 1
32 C 129
32 S 131 NFLX 1357 25
32 B 132 AMZN 2469 10
32 C 130
33 B 133 NVDA 1234 30
33 S 134 MSFT 2345 1
33 C 133
33 S 135 AAPL 1357 25
33 B 136 GOOGL 2469 10
33 C 134
34 B 137 NVDA 1234 30
34 S 138 META 2345 1
34 C 137
34 S 139 MSFT 1357 25
34 B 140 AMD 2469 10
34 C 138
35 B 141 AAPL 1234 30
35 S 142 INTC 2345 1
35 C 141
35 S 143 AAPL 1357 25
35 B 144 META 2469 10
35 C 142
36 B 145 NVDA 1234 30
36 S 146 AMD 2345 1
36 C 145
36 S 147 NFLX 1357 25
36 B 148 NFLX 2469 10
36 C 146
37 B 149 AAPL 1234 30
37 S 150 NVDA 2345 1
37 C 149
37 S 151 GOOGL 1357 25
37 B 152 NFLX 2469 10
37 C 150
38 B 153 NVDA 1234 30
38 S 154 GOOGL 2345 1
38 C 153
38 S 155 AAPL 1357 25
38 B 156 NFLX 2469 10
38 C 154
39 B 157 TSLA 1234 30
39 S 158 MSFT 2345 1
39 C 157
39 S 159 AMD 1357 25
39 B 160 AMZN 2469 10
39 C 158
40 B 161 TSLA 1234 30
40 S 162 NFLX 2345 1
40 C 161
40 S 163 AAPL 1357 25
40 B 164 META 2469 10
40 C 162
41 B 165 NFLX 1234 30
41 S 166 MSFT 2345 1
41 C 165
41 S 167 NVDA 1357 25
41 B 168 GOOGL 2469 10
41 C 166
42 B 169 AAPL 1234 30
42 S 170 AMZN 2345 1
42 C 169
42 S 171 AMD 1357 25
42 B 172 INTC 2469 10
42 C 170
43 B 173 INTC 1234 30
43 S 174 INTC 2345 1
43 C 173
43 S 175 META 1357 25
43 B 176 INTC 2469 10
43 C 174
44 B 177 MSFT 1234 30
44 S 178 TSLA 2345 1
44 C 177
44 S 179 AMZN 1357 25
44 B 180 NVDA 2469 10
44 C 178
45 B 181 AAPL 1234 30
45 S 182 TSLA 2345 1
45 C 181
45 S 183 AMZN 1357 25
45 B 184 TSLA 2469 10
45 C 182
46 B 185 AAPL 1234 30
46 S 186 AAPL 2345 1
46 C 185
46 S 187 NFLX 1357 25
46 B 188 NFLX 2469 10
46 C 186
47 B 189 META 1234 30
47 S 190 NFLX 2345 1
47 C 189
47 S 191 NFLX 1357 25
47 B 192 AMZN 2469 10
47 C 190
48 B 193 AMZN 1234 30
48 S 194 INTC 2345 1
48 C 193
48 S 195 AMD 1357 25
48 B 196 GOOGL 2469 10
48 C 194
49 B 197 AMD 1234 30
49 S 198 AMD 2345 1
49 C 197
49 S 199 NFLX 1357 25
49 B 200 NFLX 2469 10
49 C 198
.
0-49 x
